<?xml version="1.0"?>
<sdf version="1.8">
  <model name="inspection_bot">
    <pose>0 0 0.095 0 0 0</pose>
    <static>false</static>

    <link name="base_link">
      <pose>0 0 0.095 0 0 0</pose>
      <inertial>
        <mass>8.0</mass>
        <inertia>
          <ixx>0.12</ixx>
          <iyy>0.12</iyy>
          <izz>0.2</izz>
          <ixy>0</ixy>
          <ixz>0</ixz>
          <iyz>0</iyz>
        </inertia>
      </inertial>
      <collision name="base_collision">
        <geometry>
          <cylinder>
            <radius>0.18</radius>
            <length>0.18</length>
          </cylinder>
        </geometry>
        <pose>0 0 0 0 0 0</pose>
      </collision>
      <visual name="base_visual">
        <geometry>
          <cylinder>
            <radius>0.18</radius>
            <length>0.18</length>
          </cylinder>
        </geometry>
        <material>
          <ambient>0.1 0.1 0.1 1</ambient>
          <diffuse>0.2 0.2 0.25 1</diffuse>
        </material>
      </visual>

      <sensor name="lidar" type="ray">
        <pose>0 0 0.2 0 0 0</pose>
        <update_rate>12.0</update_rate>
        <ray>
          <scan>
            <horizontal>
              <samples>360</samples>
              <resolution>1</resolution>
              <min_angle>-3.14159</min_angle>
              <max_angle>3.14159</max_angle>
            </horizontal>
          </scan>
          <range>
            <min>0.12</min>
            <max>12.0</max>
            <resolution>0.01</resolution>
          </range>
        </ray>
        <topic>/scan</topic>
        <always_on>true</always_on>
      </sensor>
    </link>

    <link name="caster_link">
      <pose>-0.12 0 0.02 0 0 0</pose>
      <inertial>
        <mass>0.3</mass>
        <inertia>
          <ixx>1e-4</ixx>
          <iyy>1e-4</iyy>
          <izz>1e-4</izz>
          <ixy>0</ixy>
          <ixz>0</ixz>
          <iyz>0</iyz>
        </inertia>
      </inertial>
      <collision name="caster_collision">
        <geometry>
          <sphere>
            <radius>0.04</radius>
          </sphere>
        </geometry>
      </collision>
      <visual name="caster_visual">
        <geometry>
          <sphere>
            <radius>0.04</radius>
          </sphere>
        </geometry>
        <material>
          <ambient>0.3 0.3 0.3 1</ambient>
          <diffuse>0.4 0.4 0.4 1</diffuse>
        </material>
      </visual>
    </link>

    <joint name="caster_joint" type="ball">
      <parent>base_link</parent>
      <child>caster_link</child>
      <pose>0 0 0 0 0 0</pose>
    </joint>

    <link name="wheel_left_link">
      <pose>0 0.185 0.05 0 1.5708 0</pose>
      <inertial>
        <mass>0.5</mass>
        <inertia>
          <ixx>1e-3</ixx>
          <iyy>1e-3</iyy>
          <izz>1e-3</izz>
          <ixy>0</ixy>
          <ixz>0</ixz>
          <iyz>0</iyz>
        </inertia>
      </inertial>
      <collision name="wheel_left_collision">
        <geometry>
          <cylinder>
            <radius>0.08</radius>
            <length>0.05</length>
          </cylinder>
        </geometry>
      </collision>
      <visual name="wheel_left_visual">
        <geometry>
          <cylinder>
            <radius>0.08</radius>
            <length>0.05</length>
          </cylinder>
        </geometry>
        <material>
          <ambient>0.02 0.02 0.02 1</ambient>
          <diffuse>0.05 0.05 0.05 1</diffuse>
        </material>
      </visual>
    </link>

    <link name="wheel_right_link">
      <pose>0 -0.185 0.05 0 1.5708 0</pose>
      <inertial>
        <mass>0.5</mass>
        <inertia>
          <ixx>1e-3</ixx>
          <iyy>1e-3</iyy>
          <izz>1e-3</izz>
          <ixy>0</ixy>
          <ixz>0</ixz>
          <iyz>0</iyz>
        </inertia>
      </inertial>
      <collision name="wheel_right_collision">
        <geometry>
          <cylinder>
            <radius>0.08</radius>
            <length>0.05</length>
          </cylinder>
        </geometry>
      </collision>
      <visual name="wheel_right_visual">
        <geometry>
          <cylinder>
            <radius>0.08</radius>
            <length>0.05</length>
          </cylinder>
        </geometry>
        <material>
          <ambient>0.02 0.02 0.02 1</ambient>
          <diffuse>0.05 0.05 0.05 1</diffuse>
        </material>
      </visual>
    </link>

    <joint name="wheel_left_joint" type="revolute">
      <parent>base_link</parent>
      <child>wheel_left_link</child>
      <pose>0 0 0 0 0 0</pose>
      <axis>
        <xyz>0 1 0</xyz>
        <limit>
          <lower>-1e16</lower>
          <upper>1e16</upper>
        </limit>
        <dynamics>
          <damping>0.1</damping>
        </dynamics>
      </axis>
    </joint>

    <joint name="wheel_right_joint" type="revolute">
      <parent>base_link</parent>
      <child>wheel_right_link</child>
      <pose>0 0 0 0 0 0</pose>
      <axis>
        <xyz>0 1 0</xyz>
        <limit>
          <lower>-1e16</lower>
          <upper>1e16</upper>
        </limit>
        <dynamics>
          <damping>0.1</damping>
        </dynamics>
      </axis>
    </joint>

    <plugin name="gz::sim::systems::DiffDrive" filename="libgz-sim-diff-drive-system.so">
      <left_joint>wheel_left_joint</left_joint>
      <right_joint>wheel_right_joint</right_joint>
      <wheel_separation>0.37</wheel_separation>
      <wheel_radius>0.08</wheel_radius>
      <topic>/cmd_vel</topic>
      <odom_topic>/odom</odom_topic>
      <odom_frame>odom</odom_frame>
      <robot_base_frame>base_link</robot_base_frame>
      <odom_publisher>true</odom_publisher>
      <publish_tf>false</publish_tf>
      <max_linear_speed>0.7</max_linear_speed>
      <max_angular_speed>1.2</max_angular_speed>
    </plugin>

    <!-- PosePublisher removed; rely on ROS odom_to_tf for TF -->

  </model>
</sdf>
